Workbook

Sheet Cover
B5: Key Metrics
B6: Portfolio Value NOKm | C6: =Valuation!H12 -> 61991
B7: EPRA NTA per share | C7: =Valuation!H25 -> 169.28062
B8: Current share price NOK | C8: =11.17*9.32 -> 104.1044
B9: Discount to NTA | C9: =(C7-C8)/C7 -> 0.38501878
B11: Total debt | C11: =Debt!G6 -> 31136
B12: Loan to value | C12: =C11/C6 -> 0.50226646
B13: Interest coverage raito | C13: =Debt!G36 -> 2.1224523
B15: Investment Thesis
B16: At a 30% control premium the portfolio is acquired below appraised value, with headroom to a 54.6% premium before that disappears. Debt is capped by interest coverage rather than by asset value, at roughly 39%. LTV against the 55% a lender would otherwise allow. The returns model shows the discount is not realised on exit, because a buyer prices off yield rather than off net asset vale. Exit yield is the assumption the case stands or falls on.
B18: Model Structure
B19: Assumptions: macro, rate curves, KPI indexation
B20: Rent Roll: segment-by-segment, Oslo reversion quantified
B21: P&L: 2026E-2028E (H1 annualized, KPI growth)
B22: Debt: maturity ladder, interest expense, covenant metrics
B23: Transaction: offer pricing, NAV alignment, sources and uses, debt sizing, entry metrics
B24: Returns: levered cash flow, exit, IRR, leverage and exit yield sensitivities'
B25: Output: summary dashboard for quick reference
B26: Prepared By Robert
B27: 28.08.2026
B29: Transaction Case
B30: Control Premium | D30: =Transaction!C5 -> 0.3
B31: Offer Price Per share | D31: =Transaction!C6 -> 137.54
B32: Entry enterprise value NOKm | D32: =Transaction!C13 -> 55877.248
B33: Entry EV to appraised value | D33: =(1-Transaction!C13/Transaction!C15) -> 0.077720133
B34: Binding debt test | D34: Binds
B35: Debt and entry NOKm | D35: =Transaction!L18 -> 24198.895
B36: Sponsor equity NOKm | D36: =Transaction!L21 -> 32795.898
B37: IRR, base case | D37: =Returns!C38 -> 0.0461176
B38: Equity Multiple, base case | D38: =Returns!C39 -> 1.2395853
B40: Model Conventions
B41: Convention | C41: Meaning
B42: Black Text | C42: Formula calculated on the same sheet
B43: Green text | C43: Link to another sheet in this workbook
B44: Gray italic | C44: source reference or note
B46: Primary sources: Entra Q2 2026 quarterly report, Entra FY2025 annual report, Norges Bank Monetary Policy Report 2/26, Yahoo Finance share price 18.08.2026. Every transaction and returns assumption is listed on the Assumptions tab with its basis.

Sheet Transaction
B2: Entra Transaction Valuation | K2: Uses
B3: Offer price per share | K3: Deal Value
B4: Share price | C4: =Assumptions!E24 -> 105.8 | K4: Equity Purchase Price | L4: =C8 -> 24922.248 | O4: Assumptions!E24, Yahoo Finance, 31.08.2026
B5: Premium | C5: 0.3 | K5: Payment of Existing debt | L5: =C11 -> 30955 | O5: Assumptions!D35, model assumption
B6: Buy Price | C6: =C4*(1+C5) -> 137.54 | K6: Assumptions
B7: Outstanding Shares (in Millions) | C7: =Valuation!H35 -> 181.2 | K7: Transaction costs at( 2%) | L7: =SUM(L4:L5)*0.02 -> 1117.545 | O7: Valuation Q2-26 block, Entra Q2 2026 report, key figures
B8: New Equity value (NOKm) | C8: =C6*C7 -> 24922.248 | K8: Norwegian Document Duty | L8: Not Applicable
B9: Enterprise Metrics | C9: Current EV | D9: =(C4*C7)+C11 -> 50125.96 | K9: Total Acquisition Cost
K10: Total Uses | L10: =SUM(L4:L5)+L7 -> 56994.793
B11: Repayment Of debts | C11: 30955
B12: Equity offering value | C12: =C6*C7 -> 24922.248
B13: Entry EV | C13: =C11+C12 -> 55877.248 | K13: Sources
B14: Historical market value of Portfolio (NOKm) | C14: Q2-26 | D14: Q1-26 | E14: Q2-25 | F14: FY2025 | G14: FY2024 | K14: Debt Tests
B15: Value | C15: 60586 | D15: 61425 | E15: 62118 | F15: 61991 | G15: 69520 | K15: LTV | L15: =Assumptions!D36*C15 -> 33322.3 | O15: Entra Q2 2026 report, key figures market value of portfolio
K16: Debt Yield Test | L16: =(('P&L'!F26*4)/Assumptions!D37) -> 31511.111
B17: EPRA NRV | K17: ICR test | L17: =(('P&L'!F30)*4)/Assumptions!D38/Assumptions!D18 -> 24198.895
B18: EPRA NRV/Share | C18: =Valuation!H36 -> 163.29 | K18: Binding Test | L18: =MIN(L15:L17) -> 24198.895 | M18: =INDEX({"LTV","Debt yield","ICR"},MATCH(L18,L15:L17,0))&" test binds" -> ICR test binds
B19: Alignment for Acquisition | C19: Discounts | D19: Ratios | K19: New Values
B20: Market to EPRA | C20: =1-(C4/C18) -> 0.352073 | D20: =C4/C18 -> 0.647927 | K20: New Debt | L20: =L18 -> 24198.895 | O20: Divided: 1 minus price over NRV per share
B21: Offer price to EPRA | C21: =1-(C6/C18) -> 0.1576949 | D21: =C6/C18 -> 0.8423051 | K21: Sponsor Equity | L21: =L10-L20 -> 32795.898
B22: EV to Portfolio Value | C22: =1-(C13/C15) -> 0.077720133 | D22: =C13/C15 -> 0.92227987 | K22: Total Sources | L22: =SUM(L20:L21) -> 56994.793
B23: Maximum premium to appraised value | C23: =((C15-C11)/C7)/C4-1 -> 0.545619 | K23: Check (Sources Less Uses) | L23: =L22-L10 -> 0
B24: Maximum Premium less Actual premium | C24: =C23-C5 -> 0.245619
K26: Entry Metrics
K27: Stabilised NOI (NOKm) | L27: ='Rent Roll'!H28 -> 2754
K28: Stabilised EBITDA (NOKm) | L28: ='Rent Roll'!H30 -> 2546
K29: Net initial yield on entry | L29: =L27/C13 -> 0.049286608
K30: Price per sqm (NOK) | L30: =C13*1000000/'Rent Roll'!L8 -> 50045.945
K31: Entry LTV | L31: =L20/C15 -> 0.39941397
K32: Debt yield at entry | L32: =L27/L20 -> 0.11380685
K33: Entry EV / EBITDA | L33: =C13/L28 -> 21.947073
K34: Sponsor equity (NOKm) | L34: =L21 -> 32795.898
K35: Appraisal yield on portfolio | L35: =L27/C15 -> 0.045456046 | P35: Stabilised NOI over appraised value

Sheet Returns
B2: Returns
B4: Assumption
B5: Hold perid (Years) | D5: =Assumptions!D41 -> 5
B6: Entry net initial yield | D6: =Transaction!L29 -> 0.049286608
B7: Exit yield | D7: =Assumptions!D42+Returns!D6 -> 0.051786608 | J7: Exit underwritten above entry.
B8: All-in cost of debt | D8: =Assumptions!D18 -> 0.0543
B9: Cash tax rate | D9: =Assumptions!D45 -> 0.22
B10: Maintenance capex (NOK per sqm) | D10: =Assumptions!D43 -> 150
B11: Disposal Costs | D11: =Assumptions!D44 -> 0.01
B12: Debt at entry | D12: =Transaction!L20 -> 24198.895
B13: Sponsor Equity | D13: =Transaction!L21 -> 32795.898
B15: Levered Free Cash Flow to Equity
B16: NOKm | D16: Year 0 | E16: Year 1 | F16: Year 2 | G16: Year 3 | H16: Year 4 | I16: Year 5
B17: KPI Indexation | E17: 0.03 | F17: 0.032 | G17: 0.024 | H17: 0.024 | I17: 0.024
B18: Net operating income | E18: ='Rent Roll'!H28*(1+Returns!E17) -> 2836.62 | F18: =E18*(1+F17) -> 2927.3918 | G18: =F18*(1+G17) -> 2997.6492 | H18: =G18*(1+H17) -> 3069.5928 | I18: =H18*(1+I17) -> 3143.2631
B19: Administration costs | E19: ='Rent Roll'!H29*(1+Returns!E17) -> -214.24 | F19: =E19*(1+F17) -> -221.09568 | G19: =F19*(1+G17) -> -226.40198 | H19: =G19*(1+H17) -> -231.83562 | I19: =H19*(1+I17) -> -237.39968
B20: EBITDA | E20: =E18+E19 -> 2622.38 | F20: =F18+F19 -> 2706.2962 | G20: =G18+G19 -> 2771.2473 | H20: =H18+H19 -> 2837.7572 | I20: =I18+I19 -> 2905.8634
B21: Cash Interest | E21: =-(D12*D8) -> -1314 | F21: =E21 -> -1314 | G21: =F21 -> -1314 | H21: =G21 -> -1314 | I21: =H21 -> -1314 | J21: Interest held flat. Refinancing risk seperate scenario
B22: Maintenance Capex | E22: =-(D10*'Rent Roll'!L8/1000000*(1+E17)) -> -172.50219 | F22: =E22*(1+F17) -> -178.02226 | G22: =F22*(1+G17) -> -182.29479 | H22: =G22*(1+H17) -> -186.66986 | I22: =H22*(1+I17) -> -191.14994
B23: Cash Tax | E23: =-MAX(0,E20+E21)*D9 -> -287.8436 | F23: =-MAX(0,F20+F21)*D9 -> -306.30516 | G23: =-MAX(0,G20+G21)*D9 -> -320.5944 | H23: =-MAX(0,H20+H21)*D9 -> -335.22658 | I23: =-MAX(0,I20+I21)*D9 -> -350.20994
B24: Principal Amortisation | E24: 0 | F24: 0 | G24: 0 | H24: =-$D$12*Assumptions!$D$46 -> 0 | I24: 0
B25: Levered free cash flow to Equity | E25: =SUM(E20:E24) -> 848.03421 | F25: =SUM(F20:F24) -> 907.96875 | G25: =SUM(G20:G24) -> 954.35808 | H25: =SUM(H20:H24) -> 1001.8608 | I25: =SUM(I20:I24) -> 1050.5035
B26: Exit
B27: NOKm
B28: Stabilised NOI at exit | I28: =I18 -> 3143.2631
B29: Gross exit value | I29: =I28/D7 -> 60696.446
B30: Disposal costs | I30: =-I29*$D$11 -> -606.96446
B31: Debt outstanding at exit | I31: =-($D$12+SUM(E24:I24)) -> -24198.895
B32: Net exit proceeds to equity | I32: =SUM(I29:I31) -> 35890.587
B34: Equity Cash Flow and Returns
B35: NOKm | C35: Year 0 | D35: Year 1 | E35: Year 2 | F35: Year 3 | G35: Year 4 | H35: Year 5
B36: Equity cash flow | C36: =-D13 -> -32795.898 | D36: =E25 -> 848.03421 | E36: =F25 -> 907.96875 | F36: =G25 -> 954.35808 | G36: =H25 -> 1001.8608 | H36: =I25+I32 -> 36941.09
B38: IRR | C38: =IRR(C36:H36) -> 0.0461176
B39: Equity Multiple | C39: =SUM(D36:H36)/-C36 -> 1.2395853
B40: Cash-on-Cash, year1 | C40: =E25/-C36 -> 0.025857936
B42: Leverage Sensitivity
B43: Nokm | C43: Binding (ICR) | E43: Moderate | F43: Low
B44: Debt at Entry | C44: =D12 -> 24198.895 | E44: 21000 | F44: 15000
B45: Sponsor equity | C45: =D13 -> 32795.898 | E45: =Transaction!L10-Returns!E44 -> 35994.793 | F45: =Transaction!L10-Returns!F44 -> 41994.793
B46: EntryLTV | C46: =C44/Transaction!C15 -> 0.39941397 | E46: =E44/Transaction!C15 -> 0.34661473 | F46: =F44/Transaction!C15 -> 0.24758195
...

Sheet Assumptions
A1: .
C5: Norges Bank Policy rate_Q2_2026
C6: =4.25% -> 0.0425
C8: NIBOR forward curve
C9: =4.9% -> 0.049
C10: KPI indexation 2027E
C11: KPI indexation 2028E
C12: =3% -> 0.03
C13: KPI's | D13: 2026A | E13: 2027E | F13: 2028E
C14: Policy rate (Year-end) | D14: =4.3% -> 0.043 | E14: =4.4% -> 0.044 | F14: =3.8% -> 0.038
C15: Money Market spread | D15: =0.0015 -> 0.0015 | E15: =0.0015 -> 0.0015 | F15: =0.0015 -> 0.0015
C16: 3M NIBOR | D16: =D14+D15 -> 0.0445 | E16: =E14+E15 -> 0.0455 | F16: =F14+F15 -> 0.0395
C17: Credit Margin | D17: 0.0098 | E17: 0.0098 | F17: 0.0098
C18: All-in floating cost | D18: =D16+D17 -> 0.0543 | E18: =E16+E17 -> 0.0553 | F18: =F16+F17 -> 0.0493
C19: KPI Annual averages | D19: 0.032 | E19: 0.024 | F19: 0.021
C20: KPI Indexation applied 1 Jan | D20: 0.03 | E20: 0.032 | F20: 0.024
C21: https://www.norges-bank.no/contentassets/c1ae1dbac64d43c898f234aa2744eb4b/mpr-2-26.pdf?v=19062026160250 | D21: 3M NIBOR (avg) | E21: =4.56% -> 0.0456 | F21: =4.56% -> 0.0456 | G21: =4.56% -> 0.0456
C22: https://www.norges-bank.no/contentassets/c1ae1dbac64d43c898f234aa2744eb4b/mpr-2-26.pdf?v=19062026160250 | D22: KPI, annual avg | E22: 3.2 | F22: =2.8 -> 2.8 | G22: =2.3 -> 2.3
C23: https://www.norges-bank.no/contentassets/c1ae1dbac64d43c898f234aa2744eb4b/mpr-2-26.pdf?v=19062026160250 | D23: KPI indexation applied 1 Jan | E23: 0.032 | F23: 0.024 | G23: 0.021
C24: https://uk.finance.yahoo.com/quote/ENTRA.OL/ | D24: Share price Entra 18.08.2026/NOK | E24: 105.8
C25: TENOR | D25: NIBOR | E25: Gap to policy rate
C26: 1 week | D26: =4.26% -> 0.0426 | E26: =D26-4.25% -> 0.0001
C27: 1 month | D27: =4.32% -> 0.0432 | E27: =D27-4.25% -> 0.0007
C28: 2 months | D28: =4.45% -> 0.0445 | E28: =D28-4.25% -> 0.002
C29: 3 months | D29: =4.56% -> 0.0456 | E29: =D29-4.25% -> 0.0031
C30: 6 months | D30: =4.79% -> 0.0479 | E30: =D30-4.25% -> 0.0054
C33: Transaction Assumptions
C34: Input | D34: Value | E34: Basis
C35: Control premium | D35: 0.3
C36: Target LTV | D36: 0.55
C37: Minimum debt Yield | D37: 0.09
C38: Minimum ICR covenant | D38: 2
C39: Transaction Cost | D39: 0.02
C40: Norwegian document duty | D40: 0
C41: Hold period | D41: 5
C42: Exit yield Premium to entry | D42: 0.0025
C43: Maintenance capex (NOK per sqm) | D43: 150
C44: Disposal costs (% of gross sale) | D44: 0.01
C45: Cash tax rate | D45: 0.22
C46: Principal Amortisation | D46: 0
...

Sheet Rent Roll
G4: Rent Roll
G6: Segment | H6: Oslo | I6: Bergen/Stavanger | J6: Sandvika | K6: Drammen | L6: Total
G7: Properties (#) | H7: 44 | I7: 9 | J7: 11 | K7: 6 | L7: =SUM(Table2[[#This Row],[Oslo]:[Drammen]]) -> 70
G8: Area (sqm) | H8: 752779 | I8: 167709 | J8: 135179 | K8: 60852 | L8: =SUM(Table2[[#This Row],[Oslo]:[Drammen]]) -> 1116519
G9: Occupancy (%) | H9: 0.942 | I9: 0.917 | J9: 0.927 | K9: 0.963 | L9: =SUM(Table2[[#This Row],[Oslo]:[Drammen]]) -> 3.749
G10: WAULT | H10: 6 | I10: 5.4 | J10: 5.8 | K10: 7.1 | L10: =SUM(Table2[[#This Row],[Oslo]:[Drammen]]) -> 24.3
G11: Market value (NOKm) | H11: 43389 | I11: 6677 | J11: 4494 | K11: 2093 | L11: =SUM(Table2[[#This Row],[Oslo]:[Drammen]]) -> 56653
G12: Passing rent (NOKm) | H12: 2245 | I12: 396 | J12: 271 | K12: 130 | L12: =SUM(Table2[[#This Row],[Oslo]:[Drammen]]) -> 3042
G13: Market rent (NOKm) | H13: 2553 | I13: 442 | J13: 285 | K13: 133 | L13: =SUM(Table2[[#This Row],[Oslo]:[Drammen]]) -> 3413
G15: Derived | L15: =SUM(Table2[[#This Row],[Oslo]:[Drammen]]) -> 0
G16: Value per Sqm | H16: =H11*1000/H8 -> 57.63843 | I16: =I11*1000/I8 -> 39.813009 | J16: =J11*1000/J8 -> 33.244809 | K16: =K11*1000/K8 -> 34.394925 | L16: =L11*1000/L8 -> 50.74074
G17: Passing rent per sqm | H17: =H12*1000/H8 -> 2.982283 | I17: =I12*1000/I8 -> 2.3612328 | J17: =J12*1000/J8 -> 2.0047493 | K17: =K12*1000/K8 -> 2.1363308 | L17: =L12*1000/L8 -> 2.7245394
G18: Market rent per sqm | H18: =H13*1000/H8 -> 3.3914336 | I18: =I13*1000/I8 -> 2.6355175 | J18: =J13*1000/J8 -> 2.1083156 | K18: =K13*1000/K8 -> 2.1856307 | L18: =L13*1000/L8 -> 3.0568221
G19: Net Yield (%) | H19: =H12*(1-H22)/H11 -> 0.046971227 | I19: =I12*(1-H22)/I11 -> 0.053840491 | J19: =J12*(1-H22)/J11 -> 0.054743357 | K19: =K12*(1-H22)/K11 -> 0.056385745 | L19: =L12*(1-H22)/L11 -> 0.04874516
G20: Reversion (%) | H20: =H13/H12-1 -> 0.13719376 | I20: =I13/I12-1 -> 0.11616162 | J20: =J13/J12-1 -> 0.051660517 | K20: =K13/K12-1 -> 0.023076923 | L20: =L13/L12-1 -> 0.12195924
G22: Operating Cost ratio (from P&L) | H22: ='P&L'!F21/'P&L'!F14 -> 0.092189501
G24: Stabilised NOI for Debt Sizing
G25: Line | H25: NOKm | I25: Note
G26: Total Passing rent | H26: =L12 -> 3042 | I26: Rent roll covers the management portfolio only, ties to Valuation!H9
G27: Less Annualised operating costs | H27: =-('P&L'!F21)*4 -> -288 | I27: Q2-26 Operating costs annualised
G28: Stabilised NOI | H28: =SUM(H26:H27) -> 2754
G29: Less: annualised administrative costs | H29: =('P&L'!F29)*4 -> -208 | I29: Q2-26 administrative costs annualised
G30: Stabilised EBITDA | H30: =H28+H29 -> 2546
G32: reported NOI, Q2-26 annualised | H32: ='P&L'!F26*4 -> 2836
G33: Variance to rent roll basis | H33: =H28-H32 -> -82
G34: Variance % | H34: =H33/H32 -> -0.028913963
G38: NOI and Yield by City
G39: Metric | H39: Oslo | I39: Bergen/Stavanger | J39: Sandvika | K39: Drammen | L39: Total
G40: Passing rent | H40: =H12 -> 2245 | I40: =I12 -> 396 | J40: =J12 -> 271 | K40: =K12 -> 130 | L40: =L12 -> 3042
G41: Share portfolio area | H41: =H8/L8 -> 0.67421961 | I41: =I8/'Rent Roll'!L8 -> 0.15020703 | J41: =J8/L8 -> 0.12107183 | K41: =K8/L8 -> 0.054501536 | L41: =SUM(H41:K41) -> 1
G42: Allocated operating costs | H42: =-(H41*'P&L'!F48) -> -194.17525 | I42: =-'P&L'!F48*'Rent Roll'!I41 -> -43.259624 | J42: =-'P&L'!F48*'Rent Roll'!J41 -> -34.868687 | K42: =-K41*'P&L'!F48 -> -15.696442 | L42: =SUM(H42:K42) -> -288
G43: City NOI (NOKm) | H43: =H40+H42 -> 2050.8248 | I43: =I40+I42 -> 352.74038 | J43: =J40+J42 -> 236.13131 | K43: =K40+K42 -> 114.30356 | L43: =SUM(H43:K43) -> 2754
G44: Operating cost per sqm | H44: =-H42*1000000/H8 -> 257.94456 | I44: =-I42*1000000/I8 -> 257.94456 | J44: =-J42*1000000/J8 -> 257.94456 | K44: =-K42*1000000/K8 -> 257.94456 | L44: =AVERAGE(H44:K44) -> 257.94456
G45: NOI margin | H45: =H43/H40 -> 0.91350769 | I45: =I43/I40 -> 0.89075853 | J45: =J43/J40 -> 0.87133326 | K45: =K43/K40 -> 0.87925814 | L45: =AVERAGE(H45:K45) -> 0.8887144
G46: Net initial yield on value | H46: =H43/H11 -> 0.047266006 | I46: =I43/I11 -> 0.052829171 | J46: =J43/J11 -> 0.052543683 | K46: =K43/K11 -> 0.054612307 | L46: =AVERAGE(H46:K46) -> 0.051812792
G47: Share of portfolio NOI | H47: =H43/L43 -> 0.7446713 | I47: =I43/L43 -> 0.12808293 | J47: =J43/L43 -> 0.085741217 | K47: =K43/L43 -> 0.04150456 | L47: =SUM(H47:K47) -> 1
G48: Check: total city NOI against stabilised NOI | L48: =L43-H28 -> 0

Sheet Valuation
G5: Valuation
G8: Portfolio | H8: Column1
G9: Management Portfolio NOKm | H9: 56653
G10: Project Portfolio NOKm | H10: 4750
G11: Development Sites NOKm | H11: 588
G12: Total Property Portfolio NOKm | H12: =SUM(H9:H11) -> 61991
G14: Net debt
G15: Net nominal interest bearin debt NOKm | H15: 30887
G16: Equity Bridge
G17: IFRS equity NOKm | H17: 24750
G18: revaluation of investments made in JVs NOKm | H18: 34
G19: Deferred tax properties NOKm | H19: 6464
G20: net fair value of finanial derivatives NOKm | H20: -422
G21: EPRA NRV NOKm | H21: =SUM(H17:H20) -> 30826
G23: EPRA/Shares
G24: Shares outstanding(In millions) | H24: 182.1
A25: Difference | B25: =H28-H25 -> -2.280615 | G25: EPRA NTA per share NOKm | H25: =H21/H24 -> 169.28062
G27: Checks
G28: Reported EPRA NTA/Share | H28: 167
G31: Q2-26 Position
G32: Line | H32: NOKm
G33: Total Property Portfolio | H33: =Valuation!H12 -> 61991
G34: Net Nominal Interest bearing debt | H34: =Transaction!L5 -> 30955
G35: Shares Outstanding (millions) | H35: 181.2
G36: EPRA NRV per share (reported) | H36: 163.29
G37: EPRA NTA per share (reported) | H37: 161.45
G38: EPRA NRV (NOKm) | H38: =H35*H36 -> 29588.148
G40: Source: Entra Q2 2026 report, key figures table

Sheet Debt
F4: Position at FY25A | G4: Column1
F5: Fixed rate debt | G5: 20684
F6: Total debt | G6: 31136
F7: Floating debt | G7: =G6-G5 -> 10452
F8: Hedge ratio | G8: =G5/G6 -> 0.66431141
F9: Avg fixed rate | G9: 0.0248
F10: Avg credit margin | G10: 0.0094
F12: Fixed rate maturity ladder | G12: Column1 | H12: Column2
F13: Bucket | G13: Amount (NOKm) | H13: Interest rate
F14: <1 year | G14: 3384 | H14: 0.0196
F15: 1-2 years | G15: 3200 | H15: 0.0182
F16: 2-3 years | G16: 0 | H16: 0
F17: 3-4 years | G17: 7100 | H17: 0.0243
F18: 4-5 years | G18: 1300 | H18: 0.034
F19: 5-6 years | G19: 3900 | H19: 0.031
F20: 6-7 years | G20: 0 | H20: 0
F21: 7-8 years | G21: 800 | H21: 0.0331
F22: Total | G22: =SUM(G14:G21) -> 19684 | H22: =SUMPRODUCT(G14:G21,H14:H21)/G22 -> 0.024826072
F24: Datapoint | G24: 2026E | H24: 2027E | I24: 2028E | J24: 2029E
F25: Opening fixed debt NOKm | G25: =G5 -> 20684 | H25: =G27 -> 17300 | I25: =H27 -> 14100 | J25: =I27 -> 14100
F26: Less maturing debt NOKm | G26: =G14 -> 3384 | H26: =G15 -> 3200 | I26: =G16 -> 0 | J26: =G17 -> 7100
F27: Closing fixed NOKm | G27: =G25-G26 -> 17300 | H27: =H25-H26 -> 14100 | I27: =I25 -> 14100 | J27: =J25-J26 -> 7000
F28: Weighted avg fixed rate | G28: =SUMPRODUCT(G15:G21,H15:H21)/SUM(G15:G21) -> 0.025911043 | H28: =SUMPRODUCT(G16:G21,H16:H21)/SUM(G16:G21) -> 0.027794656 | I28: =SUMPRODUCT(G16:G21,H16:H21)/SUM(G16:G21) -> 0.027794656 | J28: =SUMPRODUCT(G18:G21,H18:H21)/SUM(G18:G21) -> 0.03193
F29: Floating debt NOKm | G29: =G6-G27 -> 13836 | H29: =G6-H27 -> 17036 | I29: =G7 -> 10452 | J29: =G6-J27 -> 24136
F30: All-in floating cost | G30: =Assumptions!D18 -> 0.0543 | H30: =Assumptions!E18 -> 0.0553 | I30: =Assumptions!F18 -> 0.0493 | J30: =I30 -> 0.0493
F31: Floating Interest expense NOKm | G31: =G29*G30 -> 751.2948 | H31: =H29*H30 -> 942.0908 | I31: =I29*I30 -> 515.2836 | J31: =J29*J30 -> 1189.9048
F32: Fixed Interest Expense NOKm | G32: =G27*G28 -> 448.26104 | H32: =H27*H28 -> 391.90466 | I32: =I27*I28 -> 391.90466 | J32: =J27*J28 -> 223.51
F33: Total Interest Expense NOKm | G33: =G31+G32 -> 1199.5558 | H33: =H31+H32 -> 1333.9955 | I33: =I31+I32 -> 907.18826 | J33: =J31+J32 -> 1413.4148
F34: ICR on stabilised EBITDA | G34: ='Rent Roll'!H30/Debt!G33 -> 2.1224523
F35: Covenant checks | G35: 2026E
F36: ICR | G36: ='Rent Roll'!H30/Debt!G33 -> 2.1224523 | H36: ='Rent Roll'!H30/Debt!H33 -> 1.9085522 | I36: ='Rent Roll'!H30/Debt!I33 -> 2.8064737

Sheet P&L
E4: P&L
E5: All amounts in NOK million | F5: Q1-26 to Q2-26 | G5: Q2-25 to Q2-26 | H5: YTD Q2-25 to YTD Q2-26
E6: Rental Income Previous Period | F6: 800 | G6: 770 | H6: =1544 -> 1544
E7: Finalised development projects | F7: 0 | G7: 18 | H7: 37
E8: Vacated properties for Redevelopment | F8: -8 | G8: -22 | H8: =-36 -> -36
E9: Acquisitions | F9: 0 | G9: 0 | H9: 0
E10: Divestments | F10: -1 | G10: -2 | H10: -3
E11: CPI growth | F11: 0 | G11: 20 | H11: 41
E12: Like-for-like growth above CPI | F12: -10 | G12: -4 | H12: 0
E13: Other | F13: 0 | G13: 0 | H13: -1
E14: Rental Income | F14: =SUM(F6:F13) -> 781 | G14: =SUM(G6:G13) -> 780 | H14: =SUM(H6:H13) -> 1582
E15: Operating Costs
E16: All amounts in NOK million | F16: Q2-26 | G16: Q1-26 | H16: Q2-25 | I16: YTD Q2-26 | J16: YTD Q2-25
E17: Maintenance | F17: 6 | G17: 6 | H17: 5 | I17: 12 | J17: 9
E18: Tax, leasehold, Insurance | F18: 17 | G18: 17 | H18: 17 | I18: 34 | J18: 35
E19: Letting and prop admin | F19: 25 | G19: 25 | H19: 19 | I19: 50 | J19: 43
E20: Direct property costs | F20: 24 | G20: 19 | H20: 17 | I20: 43 | J20: 37
E21: Operating costs | F21: =SUM(F17:F20) -> 72 | G21: =SUM(G17:G20) -> 67 | H21: =SUM(H17:H20) -> 58 | I21: =SUM(I17:I20) -> 139 | J21: =SUM(J17:J20) -> 124
E22: Interest expense & Covenant
E23: All amounts in NOK million | F23: Q2-26 | G23: Q1-26 | H23: Q2-25 | I23: YTD Q2-26 | J23: YTD Q2-25
E24: Rental Income | F24: 781 | G24: =F6 -> 800 | H24: 770
E25: Less: Operating costs | F25: -72 | G25: -67 | H25: -58
E26: NOI | F26: =F14-F21 -> 709 | G26: =G24-G21 -> 733 | H26: =H24+H25 -> 712
E27: NOI Margin | F27: =F26/F14 -> 0.9078105 | G27: =G26/G24 -> 0.91625 | H27: =H26/H24 -> 0.92467532
E29: Less Administrative costs | F29: =-52 -> -52 | G29: -49 | H29: -51
E30: Direct EBITDA | F30: =F26+F29 -> 657 | G30: =G26+G29 -> 684 | H30: =H26+H29 -> 661
E31: Direct EBITDA Margin | F31: =F30/F24 -> 0.84122919 | G31: =G30/G24 -> 0.855 | H31: =H30/H24 -> 0.85844156
E32: Interest and DSCR
E33: Interest cost | F33: 317 | G33: 302 | H33: 311
E34: Commitment fees | F34: 11 | G34: 12 | H34: =-(6+11-2-13-17-7) -> 22
E35: Applicable interest cost | F35: =SUM(F33:F34) -> 328 | G35: =SUM(G33:G34) -> 314 | H35: =SUM(H33:H34) -> 333
E36: ICR | F36: =F30/F35 -> 2.0030488 | G36: =G30/G35 -> 2.1783439 | H36: =H30/H35 -> 1.984985
E37: DSCR | F37: =F30/F35 -> 2.0030488 | G37: =G30/G35 -> 2.1783439 | H37: =H30/H35 -> 1.984985 | L37: Principal repayments are zero
E40: Operating Cost Breakdown (annualised)
E41: Cost line | F41: NOKm p.a. | G41: NOK/sqm | H41: Source
E42: Maintenance | F42: =F17*4 -> 24 | G42: =F42*1000000/'Rent Roll'!L8 -> 21.49538
E43: Property tax and leasehold | F43: =F18*4*(1-Assumptions!D51) -> 47.6 | G43: =F43*1000000/'Rent Roll'!L8 -> 42.632503
E44: Insurance | F44: =F18*4*Assumptions!D51 -> 20.4 | G44: =F44*1000000/'Rent Roll'!L8 -> 18.271073
E45: Letting and property administration | F45: =F19*4 -> 100 | G45: =F45*1000000/'Rent Roll'!L8 -> 89.564083
E46: Utilities, non-recoverable | F46: =F20*4*Assumptions!D52 -> 57.6 | G46: =F46*1000000/'Rent Roll'!L8 -> 51.588912
...

Sheet OutPut
A1: ENTRA ASA FINANCIAL MODEL SUMMARY
A4: Column1 | B4: Column2 | C4: Column3 | D4: Column4
A5: 1. VALUATION
A6: Total Property Portfolio | B6: =Valuation!H12 -> 61991 | C6: NOKm
A7: Portfolio Value per sqm | B7: =Valuation!H12/1116519 -> 0.05552167 | C7: NOK/sqm
A8: Net Debt | B8: =Valuation!H15 -> 30887 | C8: NOKm
A9: EPRA NTA per share | B9: =Valuation!H25 -> 169.28062 | C9: NOK/share
A11: 2. RENTAL PROFILE
A12: Total passing rent | B12: 3042 | C12: NOKm p.a.
A13: Total market rent | B13: 3413 | C13: NOKm p.a.
A14: Portfolio reversion potential | B14: =(B13-B12)/B12 -> 0.12195924 | C14: %
A15: Oslo market rent per sqm | B15: 3.391 | C15: NOK/sqm
A16: Oslo passing rent per sqm | B16: 2.982 | C16: NOK/sqm
A17: Oslo reversion gap | B17: =(B15-B16)/B16 -> 0.13715627 | C17: %
A19: 3. DEBT & INTEREST
A20: Metric | B20: 2026E | C20: 2027E | D20: 2028E
A21: Total Debt | B21: =Debt!G27+Debt!G29 -> 31136 | C21: =Debt!H27+Debt!H29 -> 31136 | D21: =Debt!I27+Debt!I29 -> 24552
A22: Fixed debt | B22: =Debt!G27 -> 17300 | C22: =Debt!H27 -> 14100 | D22: =Debt!I27 -> 14100
A23: Floating debt | B23: =Debt!G29 -> 13836 | C23: =Debt!H29 -> 17036 | D23: =Debt!I29 -> 10452
A24: Loan-to-Value | B24: =B21/Valuation!H12 -> 0.50226646 | C24: =C21/Valuation!H12 -> 0.50226646 | D24: =D21/Valuation!H12 -> 0.39605749
A26: 4. INTEREST EXPENSE & COVENANT
A27: Metric | B27: 2026E | C27: 2027E | D27: 2028E
A28: EBITDA | B28: ='Rent Roll'!H30 -> 2546 | C28: =Table9[[#This Row],[Column2]] -> 2546 | D28: =Table9[[#This Row],[Column3]] -> 2546
A29: Fixed interest expense | C29: =Debt!H32 -> 391.90466 | D29: =Debt!I32 -> 391.90466
A30: Floating interest expense | B30: =Debt!G31 -> 751.2948 | C30: =Debt!H31 -> 942.0908 | D30: =Debt!I31 -> 515.2836
A31: Total interest expense | B31: =Debt!G33 -> 1199.5558 | C31: =Debt!H33 -> 1333.9955 | D31: =Debt!I33 -> 907.18826
A32: Interest Coverage Ratio (ICR) | B32: =B28/B31 -> 2.1224523 | C32: =C28/C31 -> 1.9085522 | D32: =D28/D31 -> 2.8064737
A34: 5. Transaction And Returns
A35: Offer price per share | B35: =Transaction!C6 -> 137.54
A36: Entry EV | B36: =Transaction!C13 -> 55877.248
A37: Stabilised NOI | B37: =Transaction!L27 -> 2754
A38: Entry net initial Yield | B38: =Transaction!L29 -> 0.049286608
A39: Debt at entry | B39: =Transaction!L20 -> 24198.895
A40: Sponsor Equity | B40: =Transaction!L21 -> 32795.898
A41: IRR base case | B41: =Returns!C38 -> 0.0461176
A42: Equity multiple base case | B42: =Returns!C39 -> 1.2395853

Sheet Property Portfolio
A1: Portfolio By Value | F1: Portfolio by Area
A2: Management Portfolio | B2: Project portfolio | C2: Development sites | F2: Management Portfolio | G2: Project Portfolio | H2: Development sites
A3: 0.91 | B3: 0.08 | C3: 0.01 | F3: 0.85 | G3: 0.08 | H3: 0.07
A22: Geographic Exposure
A23: Portfolio by Area | G23: Portfolio By Value
A24: Oslo | B24: Bergen/Stavanger | C24: Sandvika | D24: Drammen | G24: Oslo | H24: Bergen/Stavanger | I24: Sandvika | J24: Drammen
A25: 0.67 | B25: 0.15 | C25: 0.12 | D25: 0.05 | G25: 0.77 | H25: 0.12 | I25: 0.08 | J25: 0.04

Sheet Annual_report_2025
A1: Statement of comprehensive income | N1: Balance sheet | AA1: Cash flow statement

Sheet Financial statements_2026_Q2
B1: Balance sheet | Q1: Statement of financial income | AH1: Cash flow statement
